<mujoco model="base">
  <compiler angle="radian" meshdir="meshes/" />
  <option cone="elliptic" impratio="20" />
  <size nconmax="5000" njmax="5000" />
  <visual>
      <map znear="0.001" />
  </visual>

  <asset>
  <texture builtin="flat" height="256" rgb1="1 1 1." rgb2=".2 .3 .4" type="skybox" width="256" />
        <texture builtin="checker" height="512" name="texplane" rgb1=".2 .3 .4" rgb2=".1 0.15 0.2" type="2d" width="512" />
        <material name="floorplane" reflectance="0.5" texrepeat="1 1" texture="texplane" texuniform="true" />
    <mesh file="/media/jinwoo/Disk/Research_linux/Workspace/Research/Compound_task/multi-task/furniture/env/models/assets/robots/baxter/meshes/torso/base_link.STL" name="base_link" />
    <mesh file="/media/jinwoo/Disk/Research_linux/Workspace/Research/Compound_task/multi-task/furniture/env/models/assets/robots/baxter/meshes/torso/base_link_collision.STL" name="base_link_collision" />
    <mesh file="/media/jinwoo/Disk/Research_linux/Workspace/Research/Compound_task/multi-task/furniture/env/models/assets/robots/baxter/meshes/base/PEDESTAL.STL" name="PEDESTAL" />
    <mesh file="/media/jinwoo/Disk/Research_linux/Workspace/Research/Compound_task/multi-task/furniture/env/models/assets/robots/baxter/meshes/base/pedestal_link_collision.STL" name="pedestal_link_collision" />
    <mesh file="/media/jinwoo/Disk/Research_linux/Workspace/Research/Compound_task/multi-task/furniture/env/models/assets/robots/baxter/meshes/head/H0.STL" name="H0" />
    <mesh file="/media/jinwoo/Disk/Research_linux/Workspace/Research/Compound_task/multi-task/furniture/env/models/assets/robots/baxter/meshes/head/H1.STL" name="H1" />
    <mesh file="/media/jinwoo/Disk/Research_linux/Workspace/Research/Compound_task/multi-task/furniture/env/models/assets/robots/baxter/meshes/upper_shoulder/S0.STL" name="S0" />
    <mesh file="/media/jinwoo/Disk/Research_linux/Workspace/Research/Compound_task/multi-task/furniture/env/models/assets/robots/baxter/meshes/lower_shoulder/S1.STL" name="S1" />
    <mesh file="/media/jinwoo/Disk/Research_linux/Workspace/Research/Compound_task/multi-task/furniture/env/models/assets/robots/baxter/meshes/upper_elbow/E0.STL" name="E0" />
    <mesh file="/media/jinwoo/Disk/Research_linux/Workspace/Research/Compound_task/multi-task/furniture/env/models/assets/robots/baxter/meshes/lower_elbow/E1.STL" name="E1" />
    <mesh file="/media/jinwoo/Disk/Research_linux/Workspace/Research/Compound_task/multi-task/furniture/env/models/assets/robots/baxter/meshes/upper_forearm/W0.STL" name="W0" />
    <mesh file="/media/jinwoo/Disk/Research_linux/Workspace/Research/Compound_task/multi-task/furniture/env/models/assets/robots/baxter/meshes/lower_forearm/W1.STL" name="W1" />
    <mesh file="/media/jinwoo/Disk/Research_linux/Workspace/Research/Compound_task/multi-task/furniture/env/models/assets/robots/baxter/meshes/wrist/W2.STL" name="W2" />
    <mesh file="/media/jinwoo/Disk/Research_linux/Workspace/Research/Compound_task/multi-task/furniture/env/models/assets/robots/baxter/meshes/electric_gripper/fingers/paddle_tip.STL" name="paddle_tip" />
  <mesh file="/media/jinwoo/Disk/Research_linux/Workspace/Research/Compound_task/multi-task/furniture/env/models/assets/grippers/meshes/two_finger_gripper/electric_gripper_base.STL" name="electric_gripper_base" />
        <mesh file="/media/jinwoo/Disk/Research_linux/Workspace/Research/Compound_task/multi-task/furniture/env/models/assets/grippers/meshes/two_finger_gripper/standard_narrow.STL" name="standard_narrow" />
        <mesh file="/media/jinwoo/Disk/Research_linux/Workspace/Research/Compound_task/multi-task/furniture/env/models/assets/grippers/meshes/two_finger_gripper/half_round_tip.STL" name="half_round_tip" />
    <mesh file="/media/jinwoo/Disk/Research_linux/Workspace/Research/Compound_task/multi-task/furniture/env/models/assets/objects/chair_agne_0007/leg1.stl" name="leg1" scale="0.0005 0.0005 0.0005" />
        <mesh file="/media/jinwoo/Disk/Research_linux/Workspace/Research/Compound_task/multi-task/furniture/env/models/assets/objects/chair_agne_0007/leg2.stl" name="leg2" scale="0.0005 0.0005 0.0005" />
        <mesh file="/media/jinwoo/Disk/Research_linux/Workspace/Research/Compound_task/multi-task/furniture/env/models/assets/objects/chair_agne_0007/seat.stl" name="seat" scale="0.0005 0.0005 0.0005" />
        <texture file="/media/jinwoo/Disk/Research_linux/Workspace/Research/Compound_task/multi-task/furniture/env/models/assets/objects/../textures/light-wood.png" name="tex-light-wood" type="2d" />
        <material name="light-wood" reflectance="0.5" texrepeat="20 20" texture="tex-light-wood" texuniform="true" />
    </asset>

  <actuator>
  <velocity ctrllimited="true" ctrlrange="-2 2" joint="right_s0" kv="60" />
    <velocity ctrllimited="true" ctrlrange="-2 2" joint="right_s1" kv="50" />
    <velocity ctrllimited="true" ctrlrange="-2 2" joint="right_e0" kv="20" />
    <velocity ctrllimited="true" ctrlrange="-2 2" joint="right_e1" kv="20" />
    <velocity ctrllimited="true" ctrlrange="-4 4" joint="right_w0" kv="5" />
    <velocity ctrllimited="true" ctrlrange="-4 4" joint="right_w1" kv="5" />
    <velocity ctrllimited="true" ctrlrange="-4 4" joint="right_w2" kv="5" />

    <velocity ctrllimited="true" ctrlrange="-2 2" joint="left_s0" kv="60" />
    <velocity ctrllimited="true" ctrlrange="-2 2" joint="left_s1" kv="50" />
    <velocity ctrllimited="true" ctrlrange="-2 2" joint="left_e0" kv="20" />
    <velocity ctrllimited="true" ctrlrange="-2 2" joint="left_e1" kv="20" />
    <velocity ctrllimited="true" ctrlrange="-4 4" joint="left_w0" kv="5" />
    <velocity ctrllimited="true" ctrlrange="-4 4" joint="left_w1" kv="5" />
    <velocity ctrllimited="true" ctrlrange="-4 4" joint="left_w2" kv="5" />

<position ctrllimited="true" ctrlrange="-0.0115 0.020833" forcelimited="true" forcerange="-20 20" joint="r_gripper_r_finger_joint" kp="10000" name="gripper_r_gripper_r_finger_joint" />
        <position ctrllimited="true" ctrlrange="-0.020833 0.0115" forcelimited="true" forcerange="-20 20" joint="r_gripper_l_finger_joint" kp="10000" name="gripper_r_gripper_l_finger_joint" />
    <position ctrllimited="true" ctrlrange="-0.0115 0.020833" forcelimited="true" forcerange="-20 20" joint="l_gripper_r_finger_joint" kp="10000" name="gripper_l_gripper_r_finger_joint" />
        <position ctrllimited="true" ctrlrange="-0.020833 0.0115" forcelimited="true" forcerange="-20 20" joint="l_gripper_l_finger_joint" kp="10000" name="gripper_l_gripper_l_finger_joint" />

    </actuator>

  <worldbody>
  <geom condim="3" friction="2.0 0.005 0.0001" name="floor" pos="0 0 0" rgba="0.7 0.7 0.7 1" size="0.5 0.5 0.0625" type="plane" />
        
        
        
        

        <light castshadow="true" diffuse=".8 .8 .8" dir=".5 -.3 -.8" directional="true" pos="0 0 2.0" specular="0.3 0.3 0.3" />

        
        
        
        <camera fovy="60" mode="fixed" name="frontview" pos="0 -1.2 0.9" quat="0.86 0.51 0. 0." /> 
        <camera mode="fixed" name="sideview" pos="-2.5 0. 0.5" quat="0.5468 0.4482 -0.4482 -0.5468" />
    <body name="base" pos="0.0 0.65 0.21300000000000008" quat="1 0 0 -1">
      <inertial diaginertia="0.001 0.001 0.001" mass="10" pos="0 0 0" />
      <body name="collision_head_link_1" pos="0.11 0 0.75">
        <inertial diaginertia="1e-008 1e-008 1e-008" mass="0.0001" pos="0 0 0" />
        <geom class="viz" margin="0.001" name="noviz_head_link_1_geom_1" pos="0 0 0" rgba="0.8 0.3 0.3 0.3" size="0.001" type="sphere" />
        <geom margin="0.001" name="noviz_head_link_1_geom_2" pos="-0.07 -0.04 0" rgba="0.8 0.3 0.3 0.3" size="0.22" type="sphere" />
      </body>
      <body name="collision_head_link_2" pos="0.11 0 0.75">
        <inertial diaginertia="1e-008 1e-008 1e-008" mass="0.0001" pos="0 0 0" />
        <geom margin="0.001" name="noviz_head_link_2_geom_1" pos="0 0 0" rgba="0.8 0.3 0.3 0.3" size="0.001" type="sphere" />
        <geom margin="0.001" name="noviz_head_link_2_geom_2" pos="-0.07 0.04 0" rgba="0.8 0.3 0.3 0.3" size="0.22" type="sphere" />
      </body>
      <body name="torso" pos="0 0 0">
        <inertial diaginertia="1.87139 1.66268 0.779991" mass="35.3365" pos="0 0 0" quat="0.997433 0.00167178 0.0715546 -0.00209003" />
        <geom class="viz" margin="0.001" mesh="base_link" name="torso_base_link_mesh" />
        <geom class="viz" margin="0.001" mesh="base_link_collision" name="torso_collider" type="mesh" />
        <body name="pedestal" pos="0 0 0">
          <inertial diaginertia="6.0869 5.81635 4.20915" mass="60.864" pos="0 0 0" quat="0.659267 -0.259505 -0.260945 0.655692" />
          <geom class="viz" margin="0.001" mesh="PEDESTAL" name="pedestal_mesh" rgba="0.2 0.2 0.2 1" />
          <geom margin="0.001" name="_pedestal_collider_1" pos="-.04 0 -.8" rgba="0.2 0.2 0.2 1" size=".46 .425 .16" type="box" />
          <geom margin="0.001" name="pedestal_collider_2" pos="0 0 -.35" rgba="0.2 0.2 0.2 1" size=".165 .25" type="capsule" />
        </body>
        <body name="head" pos="0.06 0 0.686">
          <inertial diaginertia="0.00474065 0.00461087 0.00199949" mass="0.547767" pos="0 0 0" quat="0.339345 0.850736 -0.347392 0.201027" />
          <joint armature=".01" axis="0 0 1" damping="0" limited="true" name="head_pan" pos="0 0 0" range="-1.5708 1.5708" type="hinge" />
          <geom class="viz" margin="0.001" mesh="H0" name="head_mesh_h0" rgba="0.2 0.2 0.2 1" />
          <body name="screen" pos="0.1227 0 0" quat="0.453099 0.542864 0.542864 0.453099">
            <inertial diaginertia="0.0040484 0.00275826 0.00150834" mass="0.440171" pos="0 0 0" quat="0.995785 0.0113501 -0.000390852 0.0910132" />
            <geom class="viz" euler="0 -1.57 0" margin="0.001" mesh="H1" name="screen_mesh_1" pos="0 0 -.03" rgba="0.5 0.1 0.1 1" />
            <geom class="viz" margin="0.001" name="display" pos="0 -0.016 0" quat="0.991445 0.130526 0 0" rgba=".9 .9 .9 1" size="0.109 0.08 0.002" type="box" />
          </body>
        </body>
        <body name="right_arm_mount" pos="0.024645 -0.219645 0.118588" quat="0.923879 0 0 -0.382684">
          <inertial diaginertia="1e-008 1e-008 1e-008" mass="0.0001" pos="0 0 0" />
          <body name="right_upper_shoulder" pos="0.055695 0 0.011038">
            <inertial diaginertia="0.0498344 0.0377511 0.0331351" mass="5.70044" pos="0.01783 0.00086 0.19127" quat="0.975667 0.0673303 -0.206117 0.0325173" />
            <joint armature=".01" axis="0 0 1" damping="0" limited="true" name="right_s0" pos="0 0 0" range="-1.70168 1.70168" type="hinge" />
            <geom class="viz" margin="0.001" mesh="S0" name="right_upper_shoulder_mesh" rgba="0.5 0.1 0.1 1" />
            <geom margin="0.001" name="right_upper_shoulder_collider" pos="0 0 0.1361" rgba="0.5 0.1 0.1 1" size="0.06 0.1361" type="cylinder" />
            <body name="right_lower_shoulder" pos="0.069 0 0.27035" quat="0.707107 -0.707107 0 0">
              <inertial diaginertia="0.0278991 0.0212327 0.0112937" mass="3.22698" pos="0.06845 0.00269 -0.00529" quat="0.447487 0.536948 0.56425 0.439391" />
              <joint armature=".01" axis="0 0 1" damping="0" limited="true" name="right_s1" pos="0 0 0" range="-2.147 1.047" type="hinge" />
              <geom class="viz" margin="0.001" mesh="S1" name="right_lower_shoulder_mesh" rgba="0.5 0.1 0.1 1" />
              <geom margin="0.001" name="right_lower_shoulder" pos="0 0 0" rgba="0.5 0.1 0.1 1" size="0.06 0.06" type="cylinder" />
              <body name="right_upper_elbow" pos="0.102 0 0" quat="0.5 0.5 0.5 0.5">
                <inertial diaginertia="0.0287695 0.0273625 0.011409" mass="4.31272" pos="-0.00276 0.00132 0.18086" quat="0.838995 -0.0423128 -0.121287 0.52876" />
                <joint armature=".01" axis="0 0 1" damping="0" limited="true" name="right_e0" pos="0 0 0" range="-3.05418 3.05418" type="hinge" />
                <geom class="viz" margin="0.001" mesh="E0" name="right_upper_elbow_mesh" rgba="0.5 0.1 0.1 1" />
                <geom margin="0.001" name="right_upper_elbow_collider_1" pos="0 0 -0.0535" rgba="0.5 0.1 0.1 1" size="0.06 0.0535" type="cylinder" />
                <geom class="viz" margin="0.001" name="right_upper_elbow_visual" pos="0 0 0.1365" size="0.06 0.1365" type="cylinder" />
                <body name="right_lower_elbow" pos="0.069 0 0.26242" quat="0.5 -0.5 -0.5 -0.5">
                  <inertial diaginertia="0.0132096 0.00950002 0.00685697" mass="2.07206" pos="0.02611 0.00159 -0.01117" quat="0.440433 0.577149 0.562777 0.395221" />
                  <joint armature=".01" axis="0 0 1" damping="0" limited="true" name="right_e1" pos="0 0 0" range="-0.05 2.618" type="hinge" />
                  <geom class="viz" margin="0.001" mesh="E1" name="right_lower_elbox_mesh" rgba="0.5 0.1 0.1 1" />
                  <geom margin="0.001" name="right_lower_elbow_collider" pos="0 0 0" rgba="0.5 0.1 0.1 1" size="0.06 0.05" type="cylinder" />
                  <body name="right_upper_forearm" pos="0.10359 0 0" quat="0.5 0.5 0.5 0.5">
                    <inertial diaginertia="0.016916 0.0165511 0.00371123" mass="2.24665" pos="-0.00168 0.0046 0.13952" quat="0.892709 -0.0256256 0.00446984 0.449882" />
                    <joint armature=".01" axis="0 0 1" damping="0" limited="true" name="right_w0" pos="0 0 0" range="-3.059 3.059" type="hinge" />
                    <geom class="viz" margin="0.001" mesh="W0" name="right_upper_forearm_mesh" rgba="0.5 0.1 0.1 1" />
                    <geom margin="0.001" name="right_upper_forearm_collider" pos="0 0 -0.044" rgba="0.5 0.1 0.1 1" size="0.06 0.044" type="cylinder" />
                    <geom class="viz" margin="0.001" name="right_upper_forearm_visual" pos="0 0 0.1" size="0.06 0.1036" type="cylinder" />
                    <body name="right_lower_forearm" pos="0.01 0 0.2707" quat="0.5 -0.5 -0.5 -0.5">
                      <inertial diaginertia="0.00708828 0.00552689 0.00379383" mass="1.60979" pos="0.06041 0.00697 0.006" quat="0.456911 0.468526 0.475683 0.587743" />
                      <joint armature=".01" axis="0 0 1" damping="0" limited="true" name="right_w1" pos="0 0 0" range="-1.5708 2.094" type="hinge" />
                      <geom class="viz" margin="0.001" mesh="W1" name="right_lower_forearm_mesh" rgba="0.5 0.1 0.1 1" />
                      <geom margin="0.001" name="right_lower_forearm_visual" pos="0 0 0" rgba="0.5 0.1 0.1 1" size="0.06 0.05" type="cylinder" />
                      <body name="right_wrist" pos="0.115975 0 0" quat="0.5 0.5 0.5 0.5">
                        <inertial diaginertia="0.0003082 0.000269928 0.000251035" mass="0.35093" pos="0.00198 0.00125 0.01855" quat="0.0594843 0.68926 -0.16016 0.704082" />
                        <joint armature=".01" axis="0 0 1" damping="0" limited="true" name="right_w2" pos="0 0 0" range="-3.059 3.059" type="hinge" />
                        <geom class="viz" margin="0.001" mesh="W2" name="right_wrist_mesh" rgba="0.1 0.1 0.1 1" />
                        <geom margin="0.001" name="right_wrist_cylinder" pos="0 0 0" rgba="0.1 0.1 0.1 1" size="0.06 0.0825" type="cylinder" />
                        <body name="right_hand" pos="0 0 0.11355">
				
                        <inertial diaginertia="1e-08 1e-08 1e-08" mass="1e-08" pos="1e-08 1e-08 1e-08" quat="0.820473 0.339851 -0.17592 0.424708" />
        <geom size="1e-08 5e-09" type="cylinder" />
        <body name="right_gripper_base" pos="0 0 0.025">
            <inertial diaginertia="3e-08 2e-08 2e-08" mass="0.3" pos="0 0 0" quat="-0.5 0.5 0.5 0.5" />
            <geom conaffinity="0" contype="0" group="1" mesh="electric_gripper_base" name="right_gripper_base_geom" quat="0 0 0.707107 0.707107" type="mesh" />
            <geom quat="0 0 0.707107 0.707107" size="0.029 0.05" type="cylinder" />
            <body name="right_gripper" pos="0 0 0.095">
                <inertial diaginertia="0 0 0" mass="0.0001" pos="0 0 0" />
                
                <site group="1" name="grip_site" pos="0 0 0" rgba="0 0 0 0" size="0.01 0.01 0.01" type="sphere" />
                
                <site group="1" name="grip_site_cylinder" pos="0 0 0" rgba="0 0 0 0" size="0.005 10" type="cylinder" />
                
                <camera fovy="75" mode="fixed" name="eye_in_hand" pos="0 0 0" quat="0 -1 1 0" />
            </body>
            
            <body name="r_gripper_l_finger" pos="0 0.01 0.02">
                <inertial diaginertia="0.01 0.01 0.01" mass="0.02" pos="0 0 0" quat="0 0 0 -1" />
                <joint axis="0 1 0" damping="100" limited="true" name="r_gripper_l_finger_joint" pos="0 0 0" range="-0.0115 0.020833" type="slide" />
                <geom conaffinity="0" contype="0" group="1" mesh="standard_narrow" name="r_gripper_l_finger" quat="0 0 0 -1" type="mesh" />
                <geom conaffinity="1" contype="0" friction="0 0 0" name="l_finger_g0" pos="0 0.01725 0.04" quat="0 0 0 -1" size="0.005 0.00675 0.0375" type="box" />
                <geom conaffinity="1" contype="0" friction="0 0 0" name="l_finger_g1" pos="-0.005 -0.003 0.0083" quat="0 0 0 -1" size="0.005 0.025 0.0085" type="box" />

                <body name="r_gripper_l_finger_tip" pos="0 0.01725 0.075">
                    <inertial diaginertia="0.01 0.01 0.01" mass="0.01" pos="0 0 0" quat="0 0 0 1" />
                    <geom conaffinity="0" contype="0" group="1" mesh="half_round_tip" name="r_gripper_l_finger_tip_geom" quat="0 0 0 1" type="mesh" />
                
                <geom conaffinity="1" contype="0" friction="1 0.5 0.5" name="l_fingertip_g0" pos="0 -0.0045 -0.015" quat="0 0 0 1" size="0.004 0.004 0.0185" type="box" />

                </body>
            </body>
            <body name="r_gripper_r_finger" pos="0 -0.01 0.02">
                <inertial diaginertia="0.01 0.01 0.01" mass="0.02" pos="0 0 0" />
                <joint axis="0 1 0" damping="100" limited="true" name="r_gripper_r_finger_joint" pos="0 0 0" range="-0.020833 0.0115" type="slide" />
                <geom conaffinity="0" contype="0" group="1" mesh="standard_narrow" name="r_gripper_r_finger" type="mesh" />
                <geom conaffinity="1" contype="0" friction="0 0 0" name="r_finger_g0" pos="0 -0.01725 0.04" size="0.005 0.00675 0.0375" type="box" />
                <geom conaffinity="1" contype="0" friction="0 0 0" name="r_finger_g1" pos="0.005 0.003 0.0083" size="0.005 0.025 0.0085" type="box" />
                <body name="r_gripper_r_finger_tip" pos="0 -0.01725 0.075">
                    <inertial diaginertia="0.01 0.01 0.01" mass="0.01" pos="0 0 0" />
                    <geom conaffinity="0" contype="0" group="1" mesh="half_round_tip" name="r_gripper_r_finger_tip_geom" type="mesh" />
                    <geom conaffinity="1" contype="0" friction="1 0.5 0.5" name="r_fingertip_g0" pos="0 0.0045 -0.015" size="0.004 0.004 0.0185" type="box" />
                </body>
            </body>
        </body>
    </body>
                      </body>
                    </body>
                  </body>
                </body>
              </body>
            </body>
          </body>
        </body>
        <body name="left_arm_mount" pos="0.024645 0.219645 0.118588" quat="0.923879 0 0 0.382684">
          <inertial diaginertia="1e-008 1e-008 1e-008" mass="0.0001" pos="0 0 0" />
          <body name="left_upper_shoulder" pos="0.055695 0 0.011038">
            <inertial diaginertia="0.0498344 0.0377511 0.0331351" mass="5.70044" pos="0.01783 0.00086 0.19127" quat="0.975667 0.0673303 -0.206117 0.0325173" />
            <joint armature=".01" axis="0 0 1" damping="0" limited="true" name="left_s0" pos="0 0 0" range="-1.70168 1.70168" type="hinge" />
            <geom class="viz" margin="0.001" mesh="S0" name="left_upper_shoulder_mesh" rgba="0.5 0.1 0.1 1" />
            <geom margin="0.001" name="left_upper_shoulder_cylinder" pos="0 0 0.1361" rgba="0.5 0.1 0.1 1" size="0.06 0.1361" type="cylinder" />
            <body name="left_lower_shoulder" pos="0.069 0 0.27035" quat="0.707107 -0.707107 0 0">
              <inertial diaginertia="0.0278991 0.0212327 0.0112937" mass="3.22698" pos="0.06845 0.00269 -0.00529" quat="0.447487 0.536948 0.56425 0.439391" />
              <joint armature=".01" axis="0 0 1" damping="0" limited="true" name="left_s1" pos="0 0 0" range="-2.147 1.047" type="hinge" />
              <geom class="viz" margin="0.001" mesh="S1" name="left_lower_shoulder_mesh" rgba="0.5 0.1 0.1 1" />
              <geom margin="0.001" name="left_lower_shoulder_cylinder" pos="0 0 0" rgba="0.5 0.1 0.1 1" size="0.06 0.06" type="cylinder" />
              <body name="left_upper_elbow" pos="0.102 0 0" quat="0.5 0.5 0.5 0.5">
                <inertial diaginertia="0.0287695 0.0273625 0.011409" mass="4.31272" pos="-0.00276 0.00132 0.18086" quat="0.838995 -0.0423128 -0.121287 0.52876" />
                <joint armature=".01" axis="0 0 1" damping="0" limited="true" name="left_e0" pos="0 0 0" range="-3.05418 3.05418" type="hinge" />
                <geom class="viz" margin="0.001" mesh="E0" name="left_upper_elbow_mesh" rgba="0.5 0.1 0.1 1" />
                <geom margin="0.001" name="left_upper_elbow_cylinder" pos="0 0 -0.0535" rgba="0.5 0.1 0.1 1" size="0.06 0.0535" type="cylinder" />
                <geom class="viz" margin="0.001" name="left_upper_elbow_visual" pos="0 0 0.1365" size="0.06 0.1365" type="cylinder" />
                <body name="left_lower_elbow" pos="0.069 0 0.26242" quat="0.5 -0.5 -0.5 -0.5">
                  <inertial diaginertia="0.0132096 0.00950002 0.00685697" mass="2.07206" pos="0.02611 0.00159 -0.01117" quat="0.440433 0.577149 0.562777 0.395221" />
                  <joint armature=".01" axis="0 0 1" damping="0" limited="true" name="left_e1" pos="0 0 0" range="-0.05 2.618" type="hinge" />
                  <geom class="viz" margin="0.001" mesh="E1" name="left_lower_elbow_mesh" rgba="0.5 0.1 0.1 1" />
                  <geom margin="0.001" name="left_lower_elbow_cylinder" pos="0 0 0" rgba="0.5 0.1 0.1 1" size="0.06 0.05" type="cylinder" />
                  <body name="left_upper_forearm" pos="0.10359 0 0" quat="0.5 0.5 0.5 0.5">
                    <inertial diaginertia="0.016916 0.0165511 0.00371123" mass="2.24665" pos="-0.00168 0.0046 0.13952" quat="0.892709 -0.0256256 0.00446984 0.449882" />
                    <joint armature=".01" axis="0 0 1" damping="0" limited="true" name="left_w0" pos="0 0 0" range="-3.059 3.059" type="hinge" />
                    <geom class="viz" margin="0.001" mesh="W0" name="left_upper_forearm_mesh" rgba="0.5 0.1 0.1 1" />
                    <geom margin="0.001" name="left_upper_forearm_cylinder" pos="0 0 -0.044" rgba="0.5 0.1 0.1 1" size="0.06 0.044" type="cylinder" />
                    <geom class="viz" margin="0.001" name="left_upper_forearm_visual" pos="0 0 0.136" size="0.06 0.136" type="cylinder" />
                    <body name="left_lower_forearm" pos="0.01 0 0.2707" quat="0.5 -0.5 -0.5 -0.5">
                      <inertial diaginertia="0.00708828 0.00552689 0.00379383" mass="1.60979" pos="0.06041 0.00697 0.006" quat="0.456911 0.468526 0.475683 0.587743" />
                      <joint armature=".01" axis="0 0 1" damping="0" limited="true" name="left_w1" pos="0 0 0" range="-1.5708 2.094" type="hinge" />
                      <geom class="viz" margin="0.001" mesh="W1" name="left_lower_forearm_mesh" rgba="0.5 0.1 0.1 1" />
                      <geom margin="0.001" name="left_lower_forearm_cylinder" pos="0 0 0" rgba="0.5 0.1 0.1 1" size="0.06 0.05" type="cylinder" />
                      <body name="left_wrist" pos="0.115975 0 0" quat="0.5 0.5 0.5 0.5">
                        <inertial diaginertia="0.0003082 0.000269928 0.000251035" mass="0.35093" pos="0.00198 0.00125 0.01855" quat="0.0594843 0.68926 -0.16016 0.704082" />
                        <joint armature=".01" axis="0 0 1" damping="0" limited="true" name="left_w2" pos="0 0 0" range="-3.059 3.059" type="hinge" />
                        <geom class="viz" margin="0.001" mesh="W2" name="left_wrist_mesh" rgba="0.1 0.1 0.1 1" />
                        <geom margin="0.001" name="left_wrist_cylinder" pos="0 0 0" rgba="0.1 0.1 0.1 1" size="0.06 0.0825" type="cylinder" />
                        <body name="left_hand" pos="0 0 0.11355">
       				 
                        <inertial diaginertia="1e-08 1e-08 1e-08" mass="1e-08" pos="1e-08 1e-08 1e-08" quat="0.820473 0.339851 -0.17592 0.424708" />
        <geom size="1e-08 5e-09" type="cylinder" />
        <body name="left_gripper_base" pos="0 0 0.025">
            <inertial diaginertia="3e-08 2e-08 2e-08" mass="0.3" pos="0 0 0" quat="-0.5 0.5 0.5 0.5" />
            <geom conaffinity="0" contype="0" group="1" mesh="electric_gripper_base" quat="0 0 0.707107 0.707107" type="mesh" />
            <geom quat="0 0 0.707107 0.707107" size="0.029 0.05" type="cylinder" />
            <body name="left_gripper" pos="0 0 0.095">
                <inertial diaginertia="0 0 0" mass="0.0001" pos="0 0 0" />
                
                <site group="1" name="l_g_grip_site" pos="0 0 0" rgba="0 0 0 0" size="0.01 0.01 0.01" type="sphere" />
                
                <site group="1" name="l_g_grip_site_cylinder" pos="0 0 0" rgba="0 0 0 0" size="0.005 10" type="cylinder" />
            </body>
            
            <body name="l_gripper_l_finger" pos="0 0.01 0.02">
                <inertial diaginertia="0.01 0.01 0.01" mass="0.02" pos="0 0 0" quat="0 0 0 -1" />
                <joint axis="0 1 0" damping="100" limited="true" name="l_gripper_l_finger_joint" pos="0 0 0" range="-0.0115 0.020833" type="slide" />
                <geom conaffinity="0" contype="0" group="1" mesh="standard_narrow" name="l_gripper_l_finger" quat="0 0 0 -1" type="mesh" />

                
                <geom conaffinity="1" contype="0" friction="0 0 0" name="l_g_l_finger_g0" pos="0 0.01725 0.04" quat="0 0 0 -1" size="0.005 0.00675 0.0375" type="box" />
                <geom conaffinity="1" contype="0" friction="0 0 0" name="l_g_l_finger_g1" pos="-0.005 -0.003 0.0083" quat="0 0 0 -1" size="0.005 0.025 0.0085" type="box" />
                <body name="l_gripper_l_finger_tip" pos="0 0.01725 0.075">
                    <inertial diaginertia="0.01 0.01 0.01" mass="0.01" pos="0 0 0" quat="0 0 0 1" />
                    <geom conaffinity="0" contype="0" group="1" mesh="half_round_tip" quat="0 0 0 1" type="mesh" />
                    <geom conaffinity="1" contype="0" friction="0 0 0" name="l_g_l_fingertip_g0" pos="0 -0.0045 -0.015" quat="0 0 0 1" size="0.004 0.004 0.0185" type="box" />
                </body>
            </body>
            
            <body name="l_gripper_r_finger" pos="0 -0.01 0.02">
                <inertial diaginertia="0.01 0.01 0.01" mass="0.02" pos="0 0 0" />
                <joint axis="0 1 0" damping="100" limited="true" name="l_gripper_r_finger_joint" pos="0 0 0" range="-0.020833 0.0115" type="slide" />
                <geom conaffinity="0" contype="0" group="1" mesh="standard_narrow" name="l_gripper_r_finger" type="mesh" />
                
                <geom conaffinity="1" contype="0" friction="0 0 0" name="l_g_r_finger_g0" pos="0 -0.01725 0.04" size="0.005 0.00675 0.0375" type="box" />
                <geom conaffinity="1" contype="0" friction="0 0 0" name="l_g_r_finger_g1" pos="0.005 0.003 0.0083" size="0.005 0.025 0.0085" type="box" />
                <body name="l_gripper_r_finger_tip" pos="0 -0.01725 0.075">
                    <inertial diaginertia="0.01 0.01 0.01" mass="0.01" pos="0 0 0" />
                    <geom conaffinity="0" contype="0" group="1" mesh="half_round_tip" type="mesh" />
                    <geom conaffinity="1" contype="0" friction="0 0 0" name="l_g_r_fingertip_g0" pos="0 0.0045 -0.015" size="0.004 0.004 0.0185" type="box" />
                </body>
            </body>
        </body>
    </body>
                      </body>
                    </body>
                  </body>
                </body>
              </body>
            </body>
          </body>
        </body>
      </body>
    </body>
  <body name="1_leg1" pos="0 0 0" quat="1 0 0 0">
            <geom conaffinity="0" contype="0" density="0" friction="1 0.5 0.5" material="light-wood" mesh="leg1" name="1_leg1-0" pos="0 0 0" rgba="0.82 0.71 0.55 1" type="mesh" />
            <geom density="100" euler="1.57 0 0" friction="1 0.5 0.5" name="noviz_collision_1_leg1_1" pos="0 0 0.19" rgba="0 0 1 1" size="0.009 0.12" solref="0.001 1" type="cylinder" />
            <geom density="100" euler="0.11 0 0" friction="1 0.5 0.5" name="noviz_collision_1_leg1_2" pos="0 0.1315 0" rgba="0 1 1 1" size="0.009 0.195" solref="0.001 1" type="cylinder" />
            <geom density="100" euler="-0.11 0 0" friction="1 0.5 0.5" name="noviz_collision_1_leg1_3" pos="0 -0.1315 0" rgba="1 0 1 1" size="0.009 0.195" solref="0.001 1" type="cylinder" />
            <site name="leg1-leg2,0,180,conn_site" pos="0.0 0.0 0.18" rgba="0 1 0 0.3" size="0.01" />
            <site name="leg1-seat,conn_site" pos="0.0 0.0 0.2" rgba="1 0 0 0.3" size="0.01" />
            <site name="1_leg1_bottom_site" pos="0 0 -0.18" rgba="0 0 1 0.3" size="0.01" />
            <site name="1_leg1_top_site" pos="0.0 0.0 0.2" rgba="0 0 1 0.3" size="0.01" />
            <site name="1_leg1_horizontal_radius_site" pos="0 0 0" rgba="0 0 1 0.3" size="0.1" />
        <site name="1_leg1" pos="0 0 0" rgba="1 0 0 0" size="0.002 0.002 0.002" type="sphere" /><joint damping="0.0001" name="1_leg1" type="free" /></body>
        <body name="2_leg2" pos="-0.005 -0.01 0" quat="1 0 0 0">
            <geom conaffinity="0" contype="0" density="0" friction="1 0.5 0.5" material="light-wood" mesh="leg2" name="2_leg2-0" pos="0 0 0" rgba="0.82 0.71 0.55 1" type="mesh" />
            <geom density="100" euler="0 1.57 0" friction="1 0.5 0.5" name="noviz_collision_2_leg2_1" pos="0 0 0.19" rgba="0 0 1 1" size="0.009 0.12" solref="0.001 1" type="cylinder" />
            <geom density="100" euler="0 -0.11 0" friction="1 0.5 0.5" name="noviz_collision_2_leg2_2" pos="0.1315 0 0" rgba="0 1 1 1" size="0.009 0.195" solref="0.001 1" type="cylinder" />
            <geom density="100" euler="0 0.11 0" friction="1 0.5 0.5" name="noviz_collision_2_leg2_3" pos="-0.1315 0 0" rgba="1 0 1 1" size="0.009 0.195" solref="0.001 1" type="cylinder" />
            <site name="leg2-leg1,0,180,conn_site" pos="0.0 0.0 0.2" rgba="0 1 0 0.3" size="0.01" />
            <site name="2_leg2_bottom_site" pos="0 0 -0.18" rgba="0 0 1 0.3" size="0.01" />
            <site name="2_leg2_top_site" pos="0.0 0.0 0.2" rgba="0 0 1 0.3" size="0.01" />
            <site name="2_leg2_horizontal_radius_site" pos="0 0 0" rgba="0 0 1 0.3" size="0.1" />
        <site name="2_leg2" pos="0 0 0" rgba="1 0 0 0" size="0.002 0.002 0.002" type="sphere" /><joint damping="0.0001" name="2_leg2" type="free" /></body>

        <body name="3_seat" pos="0 0 0.2">
            <geom conaffinity="0" contype="0" density="0" friction="1 0.5 0.5" material="light-wood" mesh="seat" name="3_seat-0" pos="0 0 0" rgba="0.82 0.71 0.55 1" type="mesh" />
            <geom density="100" euler="0 0 0" friction="1 0.5 0.5" name="noviz_collision_3_seat" pos="0 0 0.002" rgba="1 0 0 1" size="0.115 0.007" solref="0.001 1" type="cylinder" />
            <site name="seat-leg1,conn_site" pos="0.0 0.0 -0.006" rgba="1 0 0 0.3" size="0.01" />
            <site name="3_seat_bottom_site" pos="0.0 0.0 -0.006" rgba="0 0 1 0.3" size="0.003" />
            <site name="3_seat_top_site" pos="0.0 0.0 0.01" rgba="0 0 1 0.3" size="0.003" />
            <site name="3_seat_horizontal_radius_site" pos="0.006 0.006 0.0" rgba="0 0 1 0.3" size="0.1" />
        <site name="3_seat" pos="0 0 0" rgba="1 0 0 0" size="0.002 0.002 0.002" type="sphere" /><joint damping="0.0001" name="3_seat" type="free" /></body>
    </worldbody>

  <equality>
  <weld active="false" body1="2_leg2" body2="1_leg1" solimp="1 1 0.5" solref="0.01 0.3" />
        <weld active="false" body1="1_leg1" body2="3_seat" solimp="1 1 0.5" solref="0.01 0.3" />
    </equality>
<contact><exclude body1="right_upper_shoulder" body2="torso" />
    <exclude body1="right_upper_shoulder" body2="right_upper_elbow" />
    <exclude body1="right_lower_shoulder" body2="torso" />
    <exclude body1="left_upper_shoulder" body2="torso" />
    <exclude body1="left_upper_shoulder" body2="left_upper_elbow" />
    <exclude body1="left_lower_shoulder" body2="torso" />
    <exclude body1="collision_head_link_1" body2="torso" />
    <exclude body1="collision_head_link_2" body2="torso" />
  </contact><default><default class="viz">
      <geom conaffinity="0" contype="0" group="1" margin="0.001" type="mesh" />
    </default>
  </default></mujoco>